{
	"title": "CVE-2015-3206",
	"cve": "CVE-2015-3206",
	"notes": {
		"description": "The checkPassword function in python-kerberos does not authenticate the KDC it attempts to communicate with, which allows remote attackers to cause a denial of service (bad response), or have other unspecified impact by performing a man-in-the-middle attack.",
		"published": "2017-08-25",
		"modified": "2023-02-12"
	},
	"references": [
		{
			"url": "http://www.securityfocus.com/bid/74760",
			"description": "MISC:74760"
		},
		{
			"url": "http://www.openwall.com/lists/oss-security/2015/05/21/3",
			"description": "MISC:[oss-security] 20150521 CVE-2015-3206 python-kerberos: checkPassword() does not verify KDC authenticity"
		},
		{
			"url": "https://bugzilla.redhat.com/show_bug.cgi?id=1223802",
			"description": "MISC:https://bugzilla.redhat.com/show_bug.cgi?id=1223802"
		},
		{
			"url": "https://github.com/apple/ccs-pykerberos/issues/31",
			"description": "MISC:https://github.com/apple/ccs-pykerberos/issues/31"
		},
		{
			"url": "https://pypi.python.org/pypi/kerberos",
			"description": "MISC:https://pypi.python.org/pypi/kerberos"
		}
	]
}
