{
	"title": "CVE-2020-35917",
	"cve": "CVE-2020-35917",
	"notes": {
		"description": "An issue was discovered in the pyo3 crate before 0.12.4 for Rust. There is a reference-counting error and use-after-free in From<Py<T>>.",
		"published": "2020-12-31",
		"modified": "2020-12-31"
	},
	"references": [
		{
			"url": "https://rustsec.org/advisories/RUSTSEC-2020-0074.html",
			"description": "MISC:https://rustsec.org/advisories/RUSTSEC-2020-0074.html"
		}
	]
}
