{
	"title": "CVE-2022-47515",
	"cve": "CVE-2022-47515",
	"notes": {
		"description": "An issue was discovered in drachtio-server before 0.8.20. It allows remote attackers to cause a denial of service (daemon crash) via a long message in a TCP request that leads to std::length_error.",
		"published": "2022-12-17",
		"modified": "2022-12-17"
	},
	"references": [
		{
			"url": "https://github.com/drachtio/drachtio-server/commit/4cf9fe2c420b86c16442215d449d40be777c1911",
			"description": "MISC:https://github.com/drachtio/drachtio-server/commit/4cf9fe2c420b86c16442215d449d40be777c1911"
		},
		{
			"url": "https://github.com/drachtio/drachtio-server/issues/245",
			"description": "MISC:https://github.com/drachtio/drachtio-server/issues/245"
		}
	]
}
